<?xml version="1.0" ?>
<!-- =================================================================================== -->
<!-- |    This document was autogenerated by xacro from magician_standalone.urdf.xacro | -->
<!-- |    EDITING THIS FILE BY HAND IS NOT RECOMMENDED                                 | -->
<!-- |    Genetate URDF from XACRO file                                                | -->
<!-- |    ros2 run xacro xacro magician_standalone.urdf.xacro > model2_test.urdf       | -->
<!-- =================================================================================== -->

<robot name="magician" xmlns:xi="http://www.w3.org/2001/XInclude">
  <link name="magician_root_link"/>
  <link name="magician_base_link">
    <visual>
      <origin rpy="0 0 0" xyz="0 0 0"/>
      <geometry>
        <mesh filename="package://dobot_description/meshes/dae/magicianBase.dae"/>
      </geometry>
    </visual>
    <collision>
      <origin rpy="0 0 0" xyz="0 0 0"/>
      <geometry>
        <mesh filename="package://dobot_description/meshes/dae/magicianBase.dae"/>
      </geometry>
    </collision>
  </link>
  <joint name="magician_joint_base" type="fixed">
    <parent link="magician_root_link"/>
    <child link="magician_base_link"/>
    <axis xyz="0 0 0"/>
    <limit effort="2000" lower="0" upper="0" velocity="1"/>
    <origin rpy="0 0 0" xyz="0 0 0.131305"/>
    <dynamics damping="0.0" friction="0.0"/>
  </joint>
  <link name="magician_link_1">
    <visual>
      <origin rpy="0 0 0" xyz="0 0 0"/>
      <geometry>
        <mesh filename="package://dobot_description/meshes/dae/magicianLink1.dae"/>
      </geometry>
    </visual>
    <collision>
      <origin rpy="0 0 0" xyz="0 0 0"/>
      <geometry>
        <mesh filename="package://dobot_description/meshes/dae/magicianLink1.dae"/>
      </geometry>
    </collision>
  </link>
  <joint name="magician_joint_1" type="revolute">
    <parent link="magician_base_link"/>
    <child link="magician_link_1"/>
    <axis xyz="0 0 1"/>
    <limit effort="2000" lower="-2.1816615649929116" upper="2.1816615649929116" velocity="1"/>
    <origin rpy="0 0 0" xyz="0 0 0"/>
    <dynamics damping="0.0" friction="0.0"/>
  </joint>
  <link name="magician_link_2">
    <visual>
      <origin rpy="0 -0.3490658503988659 0" xyz="0 0 0"/>
      <geometry>
        <mesh filename="package://dobot_description/meshes/dae/magicianLink2.dae"/>
      </geometry>
    </visual>
    <collision>
      <origin rpy="0 -0.3490658503988659 0" xyz="0 0 0"/>
      <geometry>
        <mesh filename="package://dobot_description/meshes/dae/magicianLink2.dae"/>
      </geometry>
    </collision>
  </link>
  <joint name="magician_joint_2" type="revolute">
    <parent link="magician_link_1"/>
    <child link="magician_link_2"/>
    <axis xyz="0 1 0"/>
    <limit effort="2000" lower="-0.08726646259971647" upper="1.5707963267948966" velocity="1"/>
    <origin rpy="0 0.0 0" xyz="0 0 0.0"/>
    <dynamics damping="0.0" friction="0.0"/>
  </joint>
  <link name="magician_link_3">
    <visual>
      <origin rpy="0 -0.47123889803846897 0" xyz="0.01645236135969491 0 -0.13399373047157848"/>
      <geometry>
        <mesh filename="package://dobot_description/meshes/dae/magicianLink3.dae"/>
      </geometry>
    </visual>
    <collision>
      <origin rpy="0 -0.47123889803846897 0" xyz="0.01645236135969491 0 -0.13399373047157848"/>
      <geometry>
        <mesh filename="package://dobot_description/meshes/dae/magicianLink3.dae"/>
      </geometry>
    </collision>
  </link>
  <joint name="magician_joint_3" type="revolute">
    <parent link="magician_link_2"/>
    <child link="magician_link_3"/>
    <axis xyz="0 1 0"/>
    <limit effort="2000" lower="-0.2617993877991494" upper="1.2217304763960306" velocity="1"/>
    <origin rpy="0 0 0" xyz="0 0.0 0.135"/>
    <dynamics damping="0.0" friction="0.0"/>
  </joint>
  <link name="magician_link_virtual">
    <visual>
      <origin rpy="0 0 0" xyz="-0.17715067840465534 0 -0.058595107267811"/>
      <geometry>
        <box size="0 0 0"/>
      </geometry>
    </visual>
    <collision>
      <origin rpy="0 0 0" xyz="-0.17715067840465534 0 -0.058595107267811"/>
      <geometry>
        <box size="0 0 0"/>
      </geometry>
    </collision>
  </link>
  <joint name="magician_joint_mimic_1" type="revolute">
    <parent link="magician_link_3"/>
    <child link="magician_link_virtual"/>
    <axis xyz="0 1 0"/>
    <limit effort="2000" lower="0.0" upper="6.283185307179586" velocity="1"/>
    <origin rpy="0 0 0" xyz="0.147 0 0"/>
    <dynamics damping="0.0" friction="0.0"/>
    <mimic joint="magician_joint_2" multiplier="-1" offset="0"/>
  </joint>
  <link name="magician_link_4">
    <visual>
      <origin rpy="0 0 0" xyz="-0.17715067840465534 0 -0.058595107267811"/>
      <geometry>
        <mesh filename="package://dobot_description/meshes/dae/magicianLink4.dae"/>
      </geometry>
    </visual>
    <collision>
      <origin rpy="0 0 0" xyz="-0.17715067840465534 0 -0.058595107267811"/>
      <geometry>
        <mesh filename="package://dobot_description/meshes/dae/magicianLink4.dae"/>
      </geometry>
    </collision>
  </link>
  <joint name="magician_joint_mimic_2" type="revolute">
    <parent link="magician_link_virtual"/>
    <child link="magician_link_4"/>
    <axis xyz="0 1 0"/>
    <limit effort="2000" lower="0.0" upper="6.283185307179586" velocity="1"/>
    <origin rpy="0 0 0" xyz="0 0 0"/>
    <dynamics damping="0.0" friction="0.0"/>
    <mimic joint="magician_joint_3" multiplier="-1" offset="0"/>
  </joint>
  <link name="magician_link_gripper_core">
    <visual>
      <origin rpy="0 0 0" xyz="-8.06784046553505e-05 0 -0.027843407267811"/>
      <geometry>
        <mesh filename="package://dobot_description/meshes/dae/gripper_core.dae"/>
      </geometry>
    </visual>
    <collision>
      <origin rpy="0 0 0" xyz="-8.06784046553505e-05 0 -0.027843407267811"/>
      <geometry>
        <mesh filename="package://dobot_description/meshes/dae/gripper_core.dae"/>
      </geometry>
    </collision>
  </link>
  <joint name="magician_joint_4" type="revolute">
    <parent link="magician_link_4"/>
    <child link="magician_link_gripper_core"/>
    <axis xyz="0 0 1"/>
    <limit effort="2000" lower="-2.6179938779914944" upper="2.6179938779914944" velocity="1"/>
    <origin rpy="0 0 0" xyz="0.06 0 0"/>
    <dynamics damping="0.0" friction="0.0"/>
  </joint>
  <link name="magician_link_gripper_jaw_left">
    <visual>
      <origin rpy="0 0 0" xyz="-8.06784046553505e-05 -0.0009 -0.027843407267811"/>
      <geometry>
        <mesh filename="package://dobot_description/meshes/dae/jaw_left.dae"/>
      </geometry>
    </visual>
    <collision>
      <origin rpy="0 0 0" xyz="-8.06784046553505e-05 -0.0009 -0.027843407267811"/>
      <geometry>
        <mesh filename="package://dobot_description/meshes/dae/jaw_left.dae"/>
      </geometry>
    </collision>
  </link>
  <joint name="magician_joint_prismatic_l" type="prismatic">
    <parent link="magician_link_gripper_core"/>
    <child link="magician_link_gripper_jaw_left"/>
    <axis xyz="0 1 0 "/>
    <limit effort="2000" lower="0" upper="0.0135" velocity="1"/>
    <origin rpy="0 0 0" xyz="0 0 0"/>
    <dynamics damping="0.0" friction="0.0"/>
  </joint>
  <link name="magician_link_gripper_jaw_right">
    <visual>
      <origin rpy="0 0 0" xyz="-8.06784046553505e-05 0.0009 -0.027843407267811"/>
      <geometry>
        <mesh filename="package://dobot_description/meshes/dae/jaw_right.dae"/>
      </geometry>
    </visual>
    <collision>
      <origin rpy="0 0 0" xyz="-8.06784046553505e-05 0.0009 -0.027843407267811"/>
      <geometry>
        <mesh filename="package://dobot_description/meshes/dae/jaw_right.dae"/>
      </geometry>
    </collision>
  </link>
  <joint name="magician_joint_prismatic_r" type="prismatic">
    <parent link="magician_link_gripper_core"/>
    <child link="magician_link_gripper_jaw_right"/>
    <axis xyz="0 1 0"/>
    <limit effort="2000" lower="0" upper="-0.0135" velocity="1"/>
    <origin rpy="0 0 0" xyz="0 0 0"/>
    <dynamics damping="0.0" friction="0.0"/>
    <mimic joint="magician_joint_prismatic_l" multiplier="-1" offset="0"/>
  </joint>
</robot>
